<?xml version="1.0" encoding="utf-8"?>
<!-- This URDF was automatically created by SolidWorks to URDF Exporter! Originally created by Stephen Brawner (brawner@gmail.com) 
     Commit Version: 1.6.0-4-g7f85cfe  Build Version: 1.6.7995.38578
     For more information, please see http://wiki.ros.org/sw_urdf_exporter -->
<robot
  name="V2_URDF">
  <link
    name="base_link">
    <inertial>
      <origin
        xyz="0 0 -0.0146467924787637"
        rpy="0 0 0" />
      <mass
        value="0.0512057504117312" />
      <inertia
        ixx="1.37981603824669E-05"
        ixy="8.68974144612836E-22"
        ixz="-8.24073618421067E-21"
        iyy="1.77981603824669E-05"
        iyz="1.3464119507552E-22"
        izz="1.08856469213198E-05" />
    </inertial>
    <visual>
      <origin
        xyz="0 0 0"
        rpy="0 0 0" />
      <geometry>
        <mesh
          filename="/ThesisRosGITV1/V2_URDF/meshes/base_link.STL"/>
      </geometry>
      <material
        name="">
        <color
          rgba="0.792156862745098 0.819607843137255 0.933333333333333 1" />
      </material>
    </visual>
    <collision>
      <origin
        xyz="0 0 0"
        rpy="0 0 0" />
      <geometry>
        <mesh
          filename="/ThesisRosGITV1/V2_URDF/meshes/base_link.STL"/>
      </geometry>
    </collision>
  </link>
  <link
    name="Link1">
    <inertial>
      <origin
        xyz="0.121078672322573 -1.11022302462516E-16 -0.0031618008483858"
        rpy="0 0 0" />
      <mass
        value="0.543255526111674" />
      <inertia
        ixx="0.000126513844171624"
        ixy="-1.2880220471045E-19"
        ixz="0.000135560464128087"
        iyy="0.00211414501057547"
        iyz="3.72855352431811E-20"
        izz="0.00206697241309141" />
    </inertial>
    <visual>
      <origin
        xyz="0 0 0"
        rpy="0 0 0" />
      <geometry>
        <mesh
          filename="/ThesisRosGITV1/V2_URDF/meshes/Link1.STL" />
      </geometry>
      <material
        name="">
        <color
          rgba="0.866666666666667 0.909803921568627 1 1" />
      </material>
    </visual>
    <collision>
      <origin
        xyz="0 0 0"
        rpy="0 0 0" />
      <geometry>
        <mesh
          filename="/ThesisRosGITV1/V2_URDF/meshes/Link1.STL" />
      </geometry>
    </collision>
  </link>
  <joint
    name="J1"
    type="revolute">
    <origin
      xyz="0 0 0"
      rpy="0 0 0" />
    <parent
      link="base_link" />
    <child
      link="Link1" />
    <axis
      xyz="0 0 1" />
    <limit
      lower="-3.1415"
      upper="3.1415"
      effort="0"
      velocity="0" />
  </joint>
  <link
    name="Link2">
    <inertial>
      <origin
        xyz="0.111780972450962 0 -2.22044604925031E-16"
        rpy="0 0 0" />
      <mass
        value="0.486" />
      <inertia
        ixx="7.29000000000002E-05"
        ixy="-1.62456221224448E-20"
        ixz="1.36962499524935E-21"
        iyy="0.00166189742242131"
        iyz="3.60502643362299E-21"
        izz="0.00166189742242131" />
    </inertial>
    <visual>
      <origin
        xyz="0 0 0"
        rpy="0 0 0" />
      <geometry>
        <mesh
          filename="/ThesisRosGITV1/V2_URDF/meshes/Link2.STL" />
      </geometry>
      <material
        name="">
        <color
          rgba="0.866666666666667 0.909803921568627 1 1" />
      </material>
    </visual>
    <collision>
      <origin
        xyz="0 0 0"
        rpy="0 0 0" />
      <geometry>
        <mesh
          filename="/ThesisRosGITV1/V2_URDF/meshes/Link2.STL" />
      </geometry>
    </collision>
  </link>
  <joint
    name="J2"
    type="revolute">
    <origin
      xyz="0.2 0 -0.03"
      rpy="0 0 0" />
    <parent
      link="Link1" />
    <child
      link="Link2" />
    <axis
      xyz="0 0 1" />
    <limit
      lower="-1.57"
      upper="1.57"
      effort="0"
      velocity="0" />
  </joint>
  <link
    name="EndEffector">
    <inertial>
      <origin
        xyz="-0.00941712317023224 -1.11022302462516E-16 2.22044604925031E-16"
        rpy="0 0 0" />
      <mass
        value="0.0163971247941345" />
      <inertia
        ixx="2.65837262923016E-06"
        ixy="-7.20654902043793E-23"
        ixz="-2.86162679904832E-23"
        iyy="1.78665169918355E-06"
        iyz="7.32243042242435E-23"
        izz="1.98545560929353E-06" />
    </inertial>
    <visual>
      <origin
        xyz="0 0 0"
        rpy="0 0 0" />
      <geometry>
        <mesh
          filename="/ThesisRosGITV1/V2_URDF/meshes/EndEffector.STL" />
      </geometry>
      <material
        name="">
        <color
          rgba="0.792156862745098 0.819607843137255 0.933333333333333 1" />
      </material>
    </visual>
    <collision>
      <origin
        xyz="0 0 0"
        rpy="0 0 0" />
      <geometry>
        <mesh
          filename="/ThesisRosGITV1/V2_URDF/meshes/EndEffector.STL" />
      </geometry>
    </collision>
  </link>
  <joint
    name="J3"
    type="fixed">
    <origin
      xyz="0.23 0 0"
      rpy="0 0 0" />
    <parent
      link="Link2" />
    <child
      link="EndEffector" />
    <axis
      xyz="0 0 0" />
  </joint>
</robot>